2018-05-22 19:05:02,736 ERROR: Exception on /explore [GET] [in /home/shigaki/microblog/venv/local/lib/python2.7/site-packages/flask/app.py:1761]
Traceback (most recent call last):
  File "/home/shigaki/microblog/venv/local/lib/python2.7/site-packages/flask/app.py", line 2292, in wsgi_app
    response = self.full_dispatch_request()
  File "/home/shigaki/microblog/venv/local/lib/python2.7/site-packages/flask/app.py", line 1815, in full_dispatch_request
    rv = self.handle_user_exception(e)
  File "/home/shigaki/microblog/venv/local/lib/python2.7/site-packages/flask/app.py", line 1718, in handle_user_exception
    reraise(exc_type, exc_value, tb)
  File "/home/shigaki/microblog/venv/local/lib/python2.7/site-packages/flask/app.py", line 1813, in full_dispatch_request
    rv = self.dispatch_request()
  File "/home/shigaki/microblog/venv/local/lib/python2.7/site-packages/flask/app.py", line 1799, in dispatch_request
    return self.view_functions[rule.endpoint](**req.view_args)
  File "/home/shigaki/microblog/venv/local/lib/python2.7/site-packages/flask_login/utils.py", line 261, in decorated_view
    return func(*args, **kwargs)
  File "/home/shigaki/microblog/app/routes.py", line 62, in explore
    prev_url=prev_url)
  File "/home/shigaki/microblog/venv/local/lib/python2.7/site-packages/flask/templating.py", line 135, in render_template
    context, ctx.app)
  File "/home/shigaki/microblog/venv/local/lib/python2.7/site-packages/flask/templating.py", line 117, in _render
    rv = template.render(context)
  File "/home/shigaki/microblog/venv/local/lib/python2.7/site-packages/jinja2/environment.py", line 1008, in render
    return self.environment.handle_exception(exc_info, True)
  File "/home/shigaki/microblog/venv/local/lib/python2.7/site-packages/jinja2/environment.py", line 780, in handle_exception
    reraise(exc_type, exc_value, tb)
  File "/home/shigaki/microblog/app/templates/index.html", line 2, in top-level template code
    {% import 'bootstrap/wtf.html' as wtf %}
  File "/home/shigaki/microblog/app/templates/base.html", line 1, in top-level template code
    {% extends 'bootstrap/base.html' %}
  File "/home/shigaki/microblog/venv/local/lib/python2.7/site-packages/flask_bootstrap/templates/bootstrap/base.html", line 1, in top-level template code
    {% block doc -%}
  File "/home/shigaki/microblog/venv/local/lib/python2.7/site-packages/flask_bootstrap/templates/bootstrap/base.html", line 4, in block "doc"
    {%- block html %}
  File "/home/shigaki/microblog/venv/local/lib/python2.7/site-packages/flask_bootstrap/templates/bootstrap/base.html", line 20, in block "html"
    {% block body -%}
  File "/home/shigaki/microblog/venv/local/lib/python2.7/site-packages/flask_bootstrap/templates/bootstrap/base.html", line 21, in block "body"
    {% block navbar %}
  File "/home/shigaki/microblog/app/templates/base.html", line 23, in block "navbar"
    <li><a href="{{ url_for('news') }}">News</a><li>
  File "/home/shigaki/microblog/venv/local/lib/python2.7/site-packages/flask/helpers.py", line 356, in url_for
    return appctx.app.handle_url_build_error(error, endpoint, values)
  File "/home/shigaki/microblog/venv/local/lib/python2.7/site-packages/flask/app.py", line 2061, in handle_url_build_error
    reraise(exc_type, exc_value, tb)
  File "/home/shigaki/microblog/venv/local/lib/python2.7/site-packages/flask/helpers.py", line 345, in url_for
    force_external=external)
  File "/home/shigaki/microblog/venv/local/lib/python2.7/site-packages/werkzeug/routing.py", line 1776, in build
    raise BuildError(endpoint, values, method, self)
BuildError: Could not build url for endpoint 'news'. Did you mean 'index' instead?
2018-05-22 19:06:13,277 INFO: Microblog startup [in /home/shigaki/microblog/app/__init__.py:52]
2018-05-22 19:13:31,333 INFO: Microblog startup [in /home/shigaki/microblog/app/__init__.py:52]
2018-05-22 19:13:44,956 INFO: Microblog startup [in /home/shigaki/microblog/app/__init__.py:52]
2018-05-22 19:15:07,374 INFO: Microblog startup [in /home/shigaki/microblog/app/__init__.py:52]
2018-05-22 19:15:59,988 INFO: Microblog startup [in /home/shigaki/microblog/app/__init__.py:52]
2018-05-22 19:18:04,920 INFO: Microblog startup [in /home/shigaki/microblog/app/__init__.py:52]
2018-05-22 19:19:04,391 INFO: Microblog startup [in /home/shigaki/microblog/app/__init__.py:52]
2018-05-22 19:22:20,148 INFO: Microblog startup [in /home/shigaki/microblog/app/__init__.py:52]
2018-05-22 19:23:06,404 INFO: Microblog startup [in /home/shigaki/microblog/app/__init__.py:52]
2018-05-22 19:25:17,456 INFO: Microblog startup [in /home/shigaki/microblog/app/__init__.py:52]
2018-05-22 19:26:48,865 INFO: Microblog startup [in /home/shigaki/microblog/app/__init__.py:52]
2018-05-22 19:27:01,549 ERROR: Exception on /news [GET] [in /home/shigaki/microblog/venv/local/lib/python2.7/site-packages/flask/app.py:1761]
Traceback (most recent call last):
  File "/home/shigaki/microblog/venv/local/lib/python2.7/site-packages/flask/app.py", line 2292, in wsgi_app
    response = self.full_dispatch_request()
  File "/home/shigaki/microblog/venv/local/lib/python2.7/site-packages/flask/app.py", line 1815, in full_dispatch_request
    rv = self.handle_user_exception(e)
  File "/home/shigaki/microblog/venv/local/lib/python2.7/site-packages/flask/app.py", line 1718, in handle_user_exception
    reraise(exc_type, exc_value, tb)
  File "/home/shigaki/microblog/venv/local/lib/python2.7/site-packages/flask/app.py", line 1813, in full_dispatch_request
    rv = self.dispatch_request()
  File "/home/shigaki/microblog/venv/local/lib/python2.7/site-packages/flask/app.py", line 1799, in dispatch_request
    return self.view_functions[rule.endpoint](**req.view_args)
  File "/home/shigaki/microblog/venv/local/lib/python2.7/site-packages/flask_login/utils.py", line 261, in decorated_view
    return func(*args, **kwargs)
  File "/home/shigaki/microblog/app/routes.py", line 207, in news
    print(data['articles']['title'])
TypeError: list indices must be integers, not str
2018-05-22 19:27:20,898 INFO: Microblog startup [in /home/shigaki/microblog/app/__init__.py:52]
2018-05-22 19:28:18,766 INFO: Microblog startup [in /home/shigaki/microblog/app/__init__.py:52]
2018-05-22 19:29:00,655 INFO: Microblog startup [in /home/shigaki/microblog/app/__init__.py:52]
2018-05-23 07:51:27,956 INFO: Microblog startup [in /home/shigaki/microblog/app/__init__.py:52]
2018-05-23 08:08:58,361 INFO: Microblog startup [in /home/shigaki/microblog/app/__init__.py:52]
2018-05-23 08:09:53,550 INFO: Microblog startup [in /home/shigaki/microblog/app/__init__.py:52]
2018-05-23 08:11:29,995 INFO: Microblog startup [in /home/shigaki/microblog/app/__init__.py:52]
2018-05-23 08:11:36,760 ERROR: Exception on /news [GET] [in /home/shigaki/microblog/venv/local/lib/python2.7/site-packages/flask/app.py:1761]
Traceback (most recent call last):
  File "/home/shigaki/microblog/venv/local/lib/python2.7/site-packages/flask/app.py", line 2292, in wsgi_app
    response = self.full_dispatch_request()
  File "/home/shigaki/microblog/venv/local/lib/python2.7/site-packages/flask/app.py", line 1815, in full_dispatch_request
    rv = self.handle_user_exception(e)
  File "/home/shigaki/microblog/venv/local/lib/python2.7/site-packages/flask/app.py", line 1718, in handle_user_exception
    reraise(exc_type, exc_value, tb)
  File "/home/shigaki/microblog/venv/local/lib/python2.7/site-packages/flask/app.py", line 1813, in full_dispatch_request
    rv = self.dispatch_request()
  File "/home/shigaki/microblog/venv/local/lib/python2.7/site-packages/flask/app.py", line 1799, in dispatch_request
    return self.view_functions[rule.endpoint](**req.view_args)
  File "/home/shigaki/microblog/venv/local/lib/python2.7/site-packages/flask_login/utils.py", line 261, in decorated_view
    return func(*args, **kwargs)
  File "/home/shigaki/microblog/app/routes.py", line 206, in news
    print(data['url'])
KeyError: 'url'
2018-05-23 08:15:35,236 INFO: Microblog startup [in /home/shigaki/microblog/app/__init__.py:52]
2018-05-23 08:15:45,000 ERROR: Exception on /news [GET] [in /home/shigaki/microblog/venv/local/lib/python2.7/site-packages/flask/app.py:1761]
Traceback (most recent call last):
  File "/home/shigaki/microblog/venv/local/lib/python2.7/site-packages/flask/app.py", line 2292, in wsgi_app
    response = self.full_dispatch_request()
  File "/home/shigaki/microblog/venv/local/lib/python2.7/site-packages/flask/app.py", line 1815, in full_dispatch_request
    rv = self.handle_user_exception(e)
  File "/home/shigaki/microblog/venv/local/lib/python2.7/site-packages/flask/app.py", line 1718, in handle_user_exception
    reraise(exc_type, exc_value, tb)
  File "/home/shigaki/microblog/venv/local/lib/python2.7/site-packages/flask/app.py", line 1813, in full_dispatch_request
    rv = self.dispatch_request()
  File "/home/shigaki/microblog/venv/local/lib/python2.7/site-packages/flask/app.py", line 1799, in dispatch_request
    return self.view_functions[rule.endpoint](**req.view_args)
  File "/home/shigaki/microblog/venv/local/lib/python2.7/site-packages/flask_login/utils.py", line 261, in decorated_view
    return func(*args, **kwargs)
  File "/home/shigaki/microblog/app/routes.py", line 206, in news
    print(data['articles']['url'])
TypeError: list indices must be integers, not str
2018-05-23 08:17:06,502 INFO: Microblog startup [in /home/shigaki/microblog/app/__init__.py:52]
